Workbook

Sheet 検索条件_開発側提供
A1: 後台主地址 | B1: https://common-legacy-app-admin.us.ikemen-sengoku.jp/admin/
A2: Redmine | B2: https://redmine.ls.aws.cybird.ne.jp/issues/315490
A3: Slack | B3: https://isweetygroup.slack.com/archives/C0666R2V5BL/p1769738886049559
A5: 活動資訊 | E5: 連結生成公式用資訊
A6: 後台位置 | B6: 搜尋欄位 | C6: 關鍵字 | D6: 其他備註 | E6: 對應頁面前綴 | F6: 可查詢關鍵字 | G6: 快速連結
A7: キャンペーンバナー管理 | B7: リンク(http)： | C7: collection/203 | E7: campaign | F7: ?link= | G7: {=IF(NOT(ISBLANK(E7:E29)),IF(NOT(ISBLANK(F7:F29)), HYPERLINK($B$1&E7:E29&F7:F29&C7:C29,"Search"), HYPERLINK($B$1&E7:E29,"Page Link") ),)} -> Search
A8: エントリーフラッシュ管理 | B8: ~などで検索できます： | C8: collection/203 | E8: entryflash | G8: Page Link
A9: コレクトイベント | B9: ID | C9: 203 | D9: Mystic Matrimony | E9: isgame/collection/ | F9: all_setting/ | G9: Search
A10: セット販売管理 | B10: セット販売ID： | C10: 843 | D10: Mystic Matrimony | E10: combinedsale | F10: ?combinedsale_mst_id= | G10: Search
A11: 道具資訊
A12: 後台位置 | B12: 搜尋欄位 | C12: 關鍵字 | D12: 其他備註
A13: アイテム管理 | B13: ID | C13: 18146 | E13: itemtrial | G13: Page Link
C14: 18147
C15: 18148
C16: 18149
C17: 18150
C18: 18151
B19: アイテムCD | C19: cpn_0203001
C20: cpn_0203002
C21: it170001508
C22: it170001509
C23: it170001510
C24: it170001511
A25: 商店道具資訊
A26: 後台位置 | B26: 搜尋欄位 | C26: 關鍵字 | D26: 其他備註
A27: ショップアイテム管理 | B27: id検索 | C27: 11883 | D27: cpn_0203001
C28: 11884 | D28: cpn_0203002

Sheet 導線
A1: No | B1: 大項目 | C1: 確認方法 | D1: 確認項目 | E1: 大項目 | F1: 確認方法 | G1: 確認項目 | H1: 詳細 | I1: テスト環境 | M1: 本番環境 | Q1: 備考 | R1: テスターコメント | S1: チケットURL
I2: 確認 | J2: 担当 | K2: 担当者 | L2: 日付 | M2: 確認 | N2: 担当 | O2: 担当者 | P2: 日付
A3: =ROW()-2 -> 1 | B3: 開催告知エンフラ | C3: 管理ツール エントリーフラッシュ管理 | D3: 再生開始日時が右記の通り設定されているか | E3: 活動開始告知EF (Enter Flash) | F3: 管理工具 開場動畫管理 | G3: 播放開始日期/時間是否如右方所示設定 | H3: ='参照_概要'!$C$36 -> 46074.708 | I3: OK | J3: IW | K3: Bill | L3: 46062
A4: =ROW()-2 -> 2 | D4: 再生終了日時が右記の通り設定されているか | G4: 播放結束日期/時間是否如右方所示設定 | H4: ='参照_概要'!$D$36 -> 46080.708 | I4: OK | J4: IW | K4: Bill | L4: 46062
A5: =ROW()-2 -> 3 | C5: 実機 | D5: 左記時刻にマイページにアクセスした際、エンフラが再生されるか | F5: 實體機台 | G5: 在右方所示時間點進入「Mypage頁面(Home)」時，是否會播放EF | H5: ='参照_概要'!$C$17+1/24/60 -> 46074.709 | I5: OK | J5: IW | K5: Bill | L5: 46064 | M5: OK | N5: {=IF(M5:M25="OK",{"IW","Bill","2/12"},)} -> IW | O5: Bill | P5: 2/12
A6: =ROW()-2 -> 4 | D6: エンフラ再生後、イベントマイページへ遷移するか | G6: EF播放後，是否會轉跳至「未參加活動 TOP」頁面 | I6: OK | J6: IW | K6: Bill | L6: 46064 | M6: OK | N6: IW | O6: Bill | P6: 2/12
A7: =ROW()-2 -> 5 | B7: ランキング応援セット発売エンフラ | C7: エントリーフラッシュ管理 | D7: 再生開始日時が右記の通り設定されているか | E7: 排行榜應援禮包發售EF (Enter Flash) | F7: 管理工具 開場動畫管理 | G7: 播放開始日期/時間是否如右方所示設定 | H7: ='参照_概要'!$C$37 -> 46079.708 | I7: OK | J7: IW | K7: Bill | L7: 46062
A8: =ROW()-2 -> 6 | D8: 再生終了日時が右記の通り設定されているか | G8: 播放結束日期/時間是否如右方所示設定 | H8: ='参照_概要'!$D$37 -> 46080.708 | I8: OK | J8: IW | K8: Bill | L8: 46062
A9: =ROW()-2 -> 7 | C9: 実機 | D9: 左記時刻にマイページにアクセスした際、エンフラが再生されるか | F9: 實體機台 | G9: 在右方所示時間點進入「Mypage頁面(Home)」時，是否會播放EF | H9: ='参照_概要'!$C$37+1/24/60 -> 46079.709 | I9: OK | J9: IW | K9: Bill | L9: 46064 | M9: OK | N9: IW | O9: Bill | P9: 2/12
A10: =ROW()-2 -> 8 | D10: エンフラ再生後、イベントマイページへ遷移するか | G10: EF播放後，是否會轉跳至「活動主面」 | I10: OK | J10: IW | K10: Bill | L10: 46064 | M10: OK | N10: IW | O10: Bill | P10: 2/12
A11: =ROW()-2 -> 9 | B11: イベントバナー | C11: キャンペーンバナー管理 | D11: 公開開始日時が右記の通り設定されているか | E11: 活動橫幅 (Banner) | F11: 管理工具 活動橫幅管理 | G11: 公開開始日期/時間是否如右方所示設定 | H11: ='参照_概要'!$C$17 -> 46074.708 | I11: OK | J11: IW | K11: Bill | L11: 46062
A12: =ROW()-2 -> 10 | D12: 公開終了日時が右記の通り設定されているか | G12: 公開結束日期/時間是否如右方所示設定 | H12: ='参照_概要'!$D$17 -> 46080.708 | I12: OK | J12: IW | K12: Bill | L12: 46062
A13: =ROW()-2 -> 11 | D13: バナー文言が右記の通り設定されているか | G13: 橫幅文字是否如右方所示設定 | H13: ='参照_概要'!$E$17 -> The only thing left to do, is to fall head over heels… | I13: OK | J13: IW | K13: Bill | L13: 46062
A14: =ROW()-2 -> 12 | C14: 実機 | D14: マイページにバナー画像が表示されているか | F14: 實體機台 | G14: 在「Mypage頁面(Home)」上是否顯示橫幅圖片 | H14: ='参照_概要'!$C$17+1/24/60 -> 46074.709 | I14: OK | J14: IW | K14: Bill | L14: 46064 | M14: OK | N14: IW | O14: Bill | P14: 2/12
A15: =ROW()-2 -> 13 | D15: イベント一覧にバナー画像が表示されているか | G15: 在「活動一覽(Events)」上是否顯示橫幅圖片 | I15: OK | J15: IW | K15: Bill | L15: 46064 | M15: OK | N15: IW | O15: Bill | P15: 2/12
A16: =ROW()-2 -> 14 | D16: バナーをタップすると、イベントマイページ画面へ遷移するか | G16: 點擊橫幅後，是否會轉跳到「活動主面」 | I16: OK | J16: IW | K16: Bill | L16: 46064 | M16: OK | N16: IW | O16: Bill | P16: 2/12
A17: =ROW()-2 -> 15 | B17: セット販売バナー | C17: キャンペーンバナー管理 | D17: 公開開始日時が右記の通り設定されているか | E17: 禮包販售橫幅 (Banner) | F17: 管理工具 活動橫幅管理 | G17: 公開開始日期/時間是否如右方所示設定 | H17: ='参照_概要'!$C$18 -> 46074.708 | I17: OK | J17: IW | K17: Bill | L17: 46062
A18: =ROW()-2 -> 16 | D18: 公開終了日時が右記の通り設定されているか | G18: 公開結束日期/時間是否如右方所示設定 | H18: ='参照_概要'!$D$18 -> 46080.708 | I18: OK | J18: IW | K18: Bill | L18: 46062
A19: =ROW()-2 -> 17 | C19: 実機 | D19: ショップ画面にバナー画像が表示されているか | F19: 實體機台 | G19: 在「商店畫面(Shop)」上是否顯示橫幅圖片 | H19: ='参照_概要'!$C$17+1/24/60 -> 46074.709 | I19: OK | J19: IW | K19: Bill | L19: 46064 | M19: OK | N19: IW | O19: Bill | P19: 2/12
A20: =ROW()-2 -> 18 | D20: バナーをタップすると、セット販売画面へ遷移するか | G20: 點擊橫幅後，是否會轉跳到「禮包販售畫面」 | I20: OK | J20: IW | K20: Bill | L20: 46064 | M20: OK | N20: IW | O20: Bill | P20: 2/12
A21: =ROW()-2 -> 19 | B21: 最終ランキングバナー | C21: キャンペーンバナー管理 | D21: 公開開始日時が右記の通り設定されているか | E21: 最終排行榜橫幅 (Banner) | F21: 管理工具 活動橫幅管理 | G21: 公開開始日期/時間是否如右方所示設定 | H21: ='参照_概要'!$C$19 -> 46080.729 | I21: OK | J21: IW | K21: Bill | L21: 46062
A22: =ROW()-2 -> 20 | D22: 公開終了日時が右記の通り設定されているか | G22: 公開結束日期/時間是否如右方所示設定 | H22: ='参照_概要'!$D$19 -> 46087.729 | I22: OK | J22: IW | K22: Bill | L22: 46062
A23: =ROW()-2 -> 21 | D23: バナー文言が右記の通り設定されているか | G23: 橫幅文字是否如右方所示設定 | H23: ='参照_概要'!$E$19 -> Check your Ranking! | I23: OK | J23: IW | K23: Bill | L23: 46062
A24: =ROW()-2 -> 22 | C24: 実機 | D24: イベント一覧にバナー画像が表示されているか | F24: 實體機台 | G24: 在「活動一覽(Events)」上是否顯示橫幅圖片 | H24: ='参照_概要'!$C$19+1/24/60 -> 46080.73 | I24: OK | J24: IW | K24: Bill | L24: 46064 | M24: OK | N24: IW | O24: Bill | P24: 2/12
A25: =ROW()-2 -> 23 | D25: バナーをタップすると、最終ランキング画面へ遷移するか | G25: 點擊橫幅後，是否會轉跳到「最終排行榜畫面」 | I25: OK | J25: IW | K25: Bill | L25: 46064

Sheet 本編促進
A1: No | B1: 画面 | C1: 確認方法 | D1: 確認項目 | E1: 画面 | F1: 確認方法 | G1: 確認項目 | H1: 日時 / 詳細 | I1: テスト環境 | M1: 本番環境 | Q1: 備考 | R1: テスターコメント | S1: チケットURL
I2: 確認 | J2: 担当 | K2: 担当者 | L2: 日付 | M2: 確認 | N2: 担当 | O2: 担当者 | P2: 日付
A3: =ROW()-2 -> 1 | B3: 本編促進全体 | C3: 管理ツール コレクションイベント | D3: イベント開始日時が右記の日時に設定されているか | E3: 本篇促進活動整體 | F3: 管理工具 收集活動 | G3: 活動開始日期/時間是否如右方所示設定 | H3: ='参照_概要'!$C$17 -> 46074.708 | I3: OK | J3: IW | K3: Bill | L3: 46062
A4: =ROW()-2 -> 2 | D4: イベント終了日時が右記の日時に設定されているか | G4: 活動結束日期/時間是否如右方所示設定 | H4: ='参照_概要'!$D$17 -> 46080.708 | I4: OK | J4: IW | K4: Bill | L4: 46062
A5: =ROW()-2 -> 3 | D5: ランキング開始日時が右記の日時に設定されているか | G5: 排行榜開始日期/時間是否如右方所示設定 | H5: ='参照_概要'!$C$19 -> 46080.729 | I5: OK | J5: IW | K5: Bill | L5: 46062
A6: =ROW()-2 -> 4 | D6: ランキング終了日時が右記の日時に設定されているか | G6: 排行榜結束日期/時間是否如右方所示設定 | H6: ='参照_概要'!$D$19 -> 46087.729 | I6: OK | J6: IW | K6: Bill | L6: 46062
A7: =ROW()-2 -> 5 | B7: 未参加TOP | C7: 実機 | D7: 画面内に日本語表記が残っていないか | E7: 本篇促進活動整體 | F7: 實體機台 | G7: 畫面內的文字是否還有日文表記 (日文未殘留) | I7: OK | J7: IW | K7: Bill | L7: 46064
A8: =ROW()-2 -> 6 | D8: イベントタイトル画像が表示されているか | G8: 活動標題圖片是否顯示 | I8: OK | J8: IW | K8: Bill | L8: 46064 | M8: OK | N8: {=IF(M8:M74="OK",{"IW","Bill","2/12"},)} -> IW | O8: Bill | P8: 2/12
A9: =ROW()-2 -> 7 | D9: イベント訴求画像が表示されているか | G9: 活動宣傳圖片是否顯示 | I9: OK | J9: IW | K9: Bill | L9: 46064 | M9: OK | N9: IW | O9: Bill | P9: 2/12
A10: =ROW()-2 -> 8 | D10: 早期前半クリア特典画像が表示されているか | G10: 早期前半達成特典圖片是否顯示 | I10: OK | J10: IW | K10: Bill | L10: 46064 | M10: OK | N10: IW | O10: Bill | P10: 2/12
A11: =ROW()-2 -> 9 | D11: 早期後半クリア特典画像が表示されているか | G11: 早期後半達成特典圖片是否顯示 | I11: OK | J11: IW | K11: Bill | L11: 46064 | M11: OK | N11: IW | O11: Bill | P11: 2/12
A12: =ROW()-2 -> 10 | D12: 早期特典～イベント名～画像が表示されているか | G12: 早期特典～活動名稱～圖片是否顯示 | I12: OK | J12: IW | K12: Bill | L12: 46064 | M12: OK | N12: IW | O12: Bill | P12: 2/12
A13: =ROW()-2 -> 11 | D13: 早期全コレクション特典画像が表示されているか | G13: 早期全收集特典圖片是否顯示 | I13: OK | J13: IW | K13: Bill | L13: 46064 | M13: OK | N13: IW | O13: Bill | P13: 2/12
A14: =ROW()-2 -> 12 | D14: コレクション特典画像が表示されているか | G14: 收集特典圖片是否顯示 | I14: OK | J14: IW | K14: Bill | L14: 46064 | M14: OK | N14: IW | O14: Bill | P14: 2/12
A15: =ROW()-2 -> 13 | D15: 特別コレクション特典画像が表示されているか | G15: 特別收集特典圖片是否顯示 | I15: OK | J15: IW | K15: Bill | L15: 46064 | M15: OK | N15: IW | O15: Bill | P15: 2/12
A16: =ROW()-2 -> 14 | D16: ランキング特典画像が表示されているか | G16: 排行榜特典圖片是否顯示 | I16: OK | J16: IW | K16: Bill | L16: 46064 | M16: OK | N16: IW | O16: Bill | P16: 2/12
A17: =ROW()-2 -> 15 | D17: [ Enter ] ボタンをタップすると、イベントへ参加できるか | G17: 點擊 [ Enter ] 按鈕後，是否可以參加活動 | I17: OK | J17: IW | K17: Bill | L17: 46064 | M17: OK | N17: IW | O17: Bill | P17: 2/12
A18: =ROW()-2 -> 16 | B18: イベントマイページ | C18: 実機 | D18: 画面内に日本語表記が残っていないか | E18: 活動主頁 | F18: 實體機台 | G18: 畫面內是否沒有殘留日文標記 | I18: OK | J18: IW | K18: Bill | L18: 46064
A19: =ROW()-2 -> 17 | D19: イベントタイトル画像が表示されているか | G19: 活動標題圖片是否顯示 | I19: OK | J19: IW | K19: Bill | L19: 46064 | M19: OK | N19: IW | O19: Bill | P19: 2/12
A20: =ROW()-2 -> 18 | D20: コレクトアイテムが使用できるか | G20: 收集道具是否可以使用 | I20: OK | J20: IW | K20: Bill | L20: 46064 | M20: OK | N20: IW | O20: Bill | P20: 2/12
A21: =ROW()-2 -> 19 | D21: 1回に使用する単位が正しいか | G21: 單次使用的單位是否正確 | H21: 10 | I21: OK | J21: IW | K21: Bill | L21: 46064 | M21: OK | N21: IW | O21: Bill | P21: 2/12
A22: =ROW()-2 -> 20 | D22: 使用個数のMAX値が正しいか | G22: 使用數量的最大值是否正確 | H22: 100 | I22: OK | J22: IW | K22: Bill | L22: 46064 | M22: OK | N22: IW | O22: Bill | P22: 2/12
A23: =ROW()-2 -> 21 | D23: メニュー内のヘルプ押下で、ヘルプ画面へ遷移するか | G23: 點擊選單中的「幫助」，是否會跳轉到幫助畫面 | I23: OK | J23: IW | K23: Bill | L23: 46064 | M23: OK | N23: IW | O23: Bill | P23: 2/12
A24: =ROW()-2 -> 22 | D24: ヘルプ画面内に日本語表記が残っていないか | G24: 幫助畫面內是否沒有殘留日文標記 | I24: OK | J24: IW | K24: Bill | L24: 46064
A25: =ROW()-2 -> 23 | D25: 「イベントの説明を聞く」押下で、ストーリーが再生されるか | G25: 點擊「聽取活動說明」，故事是否會播放 | I25: OK | J25: IW | K25: Bill | L25: 46064 | M25: OK | N25: IW | O25: Bill | P25: 2/12
A26: =ROW()-2 -> 24 | D26: メニュー内のフィーバー押下で、フィーバースケジュールモーダルが表示されるか | G26: 點擊選單中的「Fever（加倍時間）」，是否會顯示 Fever 排程彈窗 | I26: OK | J26: IW | K26: Bill | L26: 46064 | M26: OK | N26: IW | O26: Bill | P26: 2/12
A27: =ROW()-2 -> 25 | D27: フィーバースケジュールモーダル内に日本語が残っていないか | G27: Fever 排程彈窗內是否沒有殘留日文 | I27: OK | J27: IW | K27: Bill | L27: 46064
A28: =ROW()-2 -> 26 | D28: 「コレクション特典」押下で、特典一覧へ遷移するか | G28: 點擊「收集特典」，是否會跳轉到特典一覽頁面 | I28: OK | J28: IW | K28: Bill | L28: 46064 | M28: OK | N28: IW | O28: Bill | P28: 2/12
A29: =ROW()-2 -> 27 | D29: 「特別コレクション特典」押下で、特典一覧へ遷移するか | G29: 點擊「特別收集特典」，是否會跳轉到特典一覽頁面 | I29: OK | J29: IW | K29: Bill | L29: 46064 | M29: OK | N29: IW | O29: Bill | P29: 2/12
A30: =ROW()-2 -> 28 | D30: 「物語を読んで恋のハートGET」押下で、ストーリーが再生されるか | G30: 點擊「閱讀故事獲得愛戀之心」，故事是否會播放
A31: =ROW()-2 -> 29 | D31: 「姫磨きで恋のハートGET」押下で、姫磨きへ遷移するか | G31: 點擊「姬磨練獲得愛戀之心」，是否會跳轉到姬磨練頁面
A32: =ROW()-2 -> 30 | D32: 「応援セットで恋のハートGET」押下で、セット販売へ遷移するか | G32: 點擊「應援禮包獲得愛戀之心」，是否會跳轉到禮包販售頁面
A33: =ROW()-2 -> 31 | D33: 「お相手変更で恋のハートGET」押下で、お相手変更へ遷移するか | G33: 點擊「變更對象獲得愛戀之心」，是否會跳轉到變更對象頁面
A34: =ROW()-2 -> 32 | D34: 任意のセット購入訴求ポップアップが表示されるか | G34: 是否會顯示任意禮包購買宣傳彈窗 | H34: 任1禮包確認 | I34: OK | J34: IW | K34: Bill | L34: 46064 | M34: OK | N34: IW | O34: Bill | P34: 2/12
A35: =ROW()-2 -> 33 | B35: ランキング | C35: 実機 | D35: 画面内に日本語表記が残っていないか | E35: 排行榜 | F35: 實體機台 | G35: 畫面內是否沒有殘留日文標記 | I35: OK | J35: IW | K35: Bill | L35: 46064
A36: =ROW()-2 -> 34 | B36: 特典一覧 | C36: 実機 | D36: 画面内に日本語表記が残っていないか | E36: 特典一覽 | F36: 實體機台 | G36: 畫面內是否沒有殘留日文標記 | I36: OK | J36: IW | K36: Bill | L36: 46064
A37: =ROW()-2 -> 35 | B37: 特典一覧 ＞特典詳細 | C37: 実機 | D37: 着用イメージ画像が表示されているか | E37: 特典一覽 ＞特典詳情 | F37: 實體機台 | G37: 穿戴形象圖片(Sample Image)是否顯示 | I37: OK | J37: IW | K37: Bill | L37: 46064 | M37: OK | N37: IW | O37: Bill | P37: 2/12
A38: =ROW()-2 -> 36 | D38: 早期前半クリア特典画像が表示されているか | G38: 早期前半達成特典圖片是否顯示 | I38: OK | J38: IW | K38: Bill | L38: 46064 | M38: OK | N38: IW | O38: Bill | P38: 2/12
A39: =ROW()-2 -> 37 | D39: 訴求画像押下で、早期前半クリア特典モーダルが表示されるか | G39: 點擊宣傳圖片後，是否會顯示早期前半達成特典彈窗 | I39: OK | J39: IW | K39: Bill | L39: 46064 | M39: OK | N39: IW | O39: Bill | P39: 2/12
A40: =ROW()-2 -> 38 | D40: 早期後半クリア特典画像が表示されているか | G40: 早期後半達成特典圖片是否顯示 | I40: OK | J40: IW | K40: Bill | L40: 46064 | M40: OK | N40: IW | O40: Bill | P40: 2/12
...

Sheet 特典
A1: No | B1: ボーナス名 | C1: 確認方法 | D1: 確認項目 | E1: 特典名稱 | F1: 確認方法 | G1: 確認項目 | H1: 取得期間/条件 | I1: table | J1: ID | K1: Column | L1: Result | M1: テスト環境 | Q1: 本番環境 | U1: 備考 | V1: テスターコメント | W1: チケットURL
M2: 確認 | N2: 担当 | O2: 担当者 | P2: 日付 | Q2: 確認 | R2: 担当 | S2: 担当者 | T2: 日付
A3: =ROW()-2 -> 1 | B3: ='参照_各種特典'!C12&" "&'参照_各種特典'!D12 -> 早期前半特典 Early Clear Bonus Gold | C3: 管理ツール コレクションイベント＞該当イベント＞各種特典 | D3: 開始日時が右記の通り設定されているか | E3: ='参照_各種特典'!C12&" "&'参照_各種特典'!D12 -> 早期前半特典 Early Clear Bonus Gold | F3: 管理工具 收集活動＞該活動＞各種特典 | G3: 開始日期時間是否按右側設定 | H3: ='参照_各種特典'!I12 -> 46074.708 | I3: BonusGroup!B5:J | J3: ce_203_bonus_group_001 | K3: 6 | L3: =IF(ISTEXT(I3:I137), VLOOKUP(J3:J137,INDIRECT(I3:I137),K3:K137,0), ) -> 46074.708 | M3: OK | N3: IW | O3: Bill | P3: 46062
A4: =ROW()-2 -> 2 | D4: 終了日時が右記の通り設定されているか | G4: 結束日期時間是否按右側設定 | H4: ='参照_各種特典'!J12 -> 46075.958 | I4: BonusGroup!B5:J | J4: ce_203_bonus_group_001 | K4: 7 | L4: =IF(ISTEXT(I4:I138), VLOOKUP(J4:J138,INDIRECT(I4:I138),K4:K138,0), ) -> 46075.958 | M4: OK | N4: IW | O4: Bill | P4: 46062
A5: =ROW()-2 -> 3 | D5: 特典内容が右記の通り設定されているか | G5: 特典內容是否按右側設定 | H5: ='参照_各種特典'!F12 -> Blue Anemone Hair Clip | I5: Bonus!A5:L | J5: ce_203_bonus_group_001 | K5: 6 | L5: =IF(ISTEXT(I5:I139), VLOOKUP(J5:J139,INDIRECT(I5:I139),K5:K139,0), ) -> Blue Anemone Hair Clip | M5: OK | N5: IW | O5: Bill | P5: 46063 | U5: ①ボーナス詳細＞確認を押下後、遷移先で「プレゼントID」を確認する ②プレゼント登録ページで、①の「プレゼントID」を検索し、表示されたアイテムが仕様書通りかを確認する | V5: 2026/2/9 驗證單配置資料與後台不符
A6: =ROW()-2 -> 4 | C6: コレクションイベント＞該当イベント＞エンジン設定＞EARLY_BONUS_GOLDの値 | D6: 取得条件の数値が右記の通り設定されているか | F6: 收集活動＞該活動＞引擎設定＞EARLY_BONUS_GOLD的值 | G6: 取得條件的數值是否按右側設定 | H6: 140 | I6: BonusGroup!B5:J | J6: ce_203_bonus_group_001 | K6: 9 | L6: =IF(ISTEXT(I6:I140), VLOOKUP(J6:J140,INDIRECT(I6:I140),K6:K140,0), ) -> 140 | M6: OK | N6: IW | O6: Bill | P6: 46062 | U6: IDの数値が大きい方が採用される
A7: =ROW()-2 -> 5 | C7: 実機 | D7: 特典一覧にてモーダル内の特典内容が右記の通り表示されているか | F7: 實體機台 | G7: 特典一覽中的彈窗內特典內容是否按右側顯示 | H7: ='参照_各種特典'!G13 -> Collect 140 Hearts by 2/22 11:00 PM PST for this! | I7: BonusGroup!B5:J | J7: ce_203_bonus_group_001 | K7: 5 | L7: =IF(ISTEXT(I7:I141), VLOOKUP(J7:J141,INDIRECT(I7:I141),K7:K141,0), ) -> Collect 140 Hearts by 2/22 11:00 PM PST for this! | M7: OK | N7: IW | O7: Bill | P7: 46064 | V7: 2026/2/9 驗證單配置資料與後台不符，驗證單資料時間錯誤
A8: =ROW()-2 -> 6 | D8: サムネイル画像が表示されているか | G8: 是否正常顯示縮圖 | L8: =IF(ISTEXT(I8:I142), VLOOKUP(J8:J142,INDIRECT(I8:I142),K8:K142,0), ) | M8: OK | N8: IW | O8: Bill | P8: 46064 | Q8: OK | R8: {=IF(Q8:Q137="OK",{"IW","Bill","2/12"},)} -> IW | S8: Bill | T8: 2/12
A9: =ROW()-2 -> 7 | B9: ='参照_各種特典'!C14&" "&'参照_各種特典'!D14 -> 早期後半特典 Early Clear Bonus Silver | C9: コレクションイベント＞該当イベント＞各種特典 | D9: 開始日時が右記の通り設定されているか | E9: ='参照_各種特典'!C14&" "&'参照_各種特典'!D14 -> 早期後半特典 Early Clear Bonus Silver | F9: 收集活動＞該活動＞各種特典 | G9: 開始日期時間是否按右側設定 | H9: ='参照_各種特典'!I14 -> 46074.708 | I9: BonusGroup!B5:J | J9: ce_203_bonus_group_002 | K9: 6 | L9: =IF(ISTEXT(I9:I143), VLOOKUP(J9:J143,INDIRECT(I9:I143),K9:K143,0), ) -> 46074.708 | M9: OK | N9: IW | O9: Bill | P9: 46062
A10: =ROW()-2 -> 8 | D10: 終了日時が右記の通り設定されているか | G10: 結束日期時間是否按右側設定 | H10: ='参照_各種特典'!J14 -> 46076.958 | I10: BonusGroup!B5:J | J10: ce_203_bonus_group_002 | K10: 7 | L10: =IF(ISTEXT(I10:I144), VLOOKUP(J10:J144,INDIRECT(I10:I144),K10:K144,0), ) -> 46076.958 | M10: OK | N10: IW | O10: Bill | P10: 46062
A11: =ROW()-2 -> 9 | D11: 特典内容が右記の通り設定されているか | G11: 特典內容是否按右側設定 | H11: ='参照_各種特典'!F14 -> Shining Silver Ash Hair | I11: Bonus!A5:L | J11: ce_203_bonus_group_002 | K11: 6 | L11: =IF(ISTEXT(I11:I145), VLOOKUP(J11:J145,INDIRECT(I11:I145),K11:K145,0), ) -> Shining Silver Ash Hair | M11: OK | N11: IW | O11: Bill | P11: 46063 | V11: 2026/2/9 驗證單配置資料與後台不符
A12: =ROW()-2 -> 10 | C12: コレクションイベント＞該当イベント＞エンジン設定＞EARLY_BONUS_SILVERの値 | D12: 取得条件の数値が右記の通り設定されているか | F12: 收集活動＞該活動＞引擎設定＞EARLY_BONUS_SILVER的值 | G12: 取得條件的數值是否按右側設定 | H12: 240 | I12: BonusGroup!B5:J | J12: ce_203_bonus_group_002 | K12: 9 | L12: =IF(ISTEXT(I12:I146), VLOOKUP(J12:J146,INDIRECT(I12:I146),K12:K146,0), ) -> 240 | M12: OK | N12: IW | O12: Bill | P12: 46062 | U12: IDの数値が大きい方が採用される
A13: =ROW()-2 -> 11 | C13: 実機 | D13: 特典一覧にてモーダル内の特典内容が右記の通り表示されているか | F13: 實體機台 | G13: 特典一覽中的彈窗內特典內容是否按右側顯示 | H13: ='参照_各種特典'!G15 -> Collect 240 Hearts by 2/23 11:00 PM PST for this! | I13: BonusGroup!B5:J | J13: ce_203_bonus_group_002 | K13: 5 | L13: =IF(ISTEXT(I13:I147), VLOOKUP(J13:J147,INDIRECT(I13:I147),K13:K147,0), ) -> Collect 240 Hearts by 2/23 11:00 PM PST for this! | M13: OK | N13: IW | O13: Bill | P13: 46064 | V13: 2026/2/9 驗證單配置資料與後台不符，驗證單資料時間錯誤
A14: =ROW()-2 -> 12 | D14: サムネイル画像が表示されているか | G14: 是否正常顯示縮圖 | L14: =IF(ISTEXT(I14:I148), VLOOKUP(J14:J148,INDIRECT(I14:I148),K14:K148,0), ) | M14: OK | N14: IW | O14: Bill | P14: 46064 | Q14: OK | R14: IW | S14: Bill | T14: 2/12
A15: =ROW()-2 -> 13 | B15: ='参照_各種特典'!C16&" "&'参照_各種特典'!D16 -> 早期～演技派な彼編～特典 Early Clear Bonus Mystic Matrimony ~My Fated Bride~ | C15: コレクションイベント＞該当イベント＞各種特典 | D15: 開始日時が右記の通り設定されているか | E15: ='参照_各種特典'!C16&" "&'参照_各種特典'!D16 -> 早期～演技派な彼編～特典 Early Clear Bonus Mystic Matrimony ~My Fated Bride~ | F15: 收集活動＞該活動＞各種特典 | G15: 開始日期時間是否按右側設定 | H15: ='参照_各種特典'!I16 -> 46074.708 | I15: BonusGroup!B5:J | J15: ce_203_bonus_group_003 | K15: 6 | L15: =IF(ISTEXT(I15:I149), VLOOKUP(J15:J149,INDIRECT(I15:I149),K15:K149,0), ) -> 46074.708 | M15: OK | N15: IW | O15: Bill | P15: 46062
A16: =ROW()-2 -> 14 | D16: 終了日時が右記の通り設定されているか | G16: 結束日期時間是否按右側設定 | H16: ='参照_各種特典'!J16 -> 46077.958 | I16: BonusGroup!B5:J | J16: ce_203_bonus_group_003 | K16: 7 | L16: =IF(ISTEXT(I16:I150), VLOOKUP(J16:J150,INDIRECT(I16:I150),K16:K150,0), ) -> 46077.958 | M16: OK | N16: IW | O16: Bill | P16: 46063 | V16: 2026/2/9 驗證單配置資料與後台不符
A17: =ROW()-2 -> 15 | D17: 特典内容が右記の通り設定されているか | G17: 特典內容是否按右側設定 | H17: ='参照_各種特典'!F16 -> Effect: Shiny White Spider Lily | I17: Bonus!A5:L | J17: ce_203_bonus_group_003 | K17: 6 | L17: =IF(ISTEXT(I17:I151), VLOOKUP(J17:J151,INDIRECT(I17:I151),K17:K151,0), ) -> Effect: Shiny White Spider Lily | M17: OK | N17: IW | O17: Bill | P17: 46063 | V17: 2026/2/9 驗證單配置資料與後台不符
A18: =ROW()-2 -> 16 | C18: コレクションイベント＞該当イベント＞エンジン設定＞EARLY_BONUS_COPPERの値 | D18: 取得条件の数値が右記の通り設定されているか | F18: 收集活動＞該活動＞引擎設定＞EARLY_BONUS_COPPER的值 | G18: 取得條件的數值是否按右側設定 | H18: 400 | I18: BonusGroup!B5:J | J18: ce_203_bonus_group_003 | K18: 9 | L18: =IF(ISTEXT(I18:I152), VLOOKUP(J18:J152,INDIRECT(I18:I152),K18:K152,0), ) -> 400 | M18: OK | N18: IW | O18: Bill | P18: 46062 | U18: IDの数値が大きい方が採用される
A19: =ROW()-2 -> 17 | C19: 実機 | D19: 特典一覧にてモーダル内の特典内容が右記の通り表示されているか | F19: 實體機台 | G19: 特典一覽中的彈窗內特典內容是否按右側顯示 | H19: ='参照_各種特典'!G17 -> Collect 400 Hearts by 2/24 11:00 PM PST for this! | I19: BonusGroup!B5:J | J19: ce_203_bonus_group_003 | K19: 5 | L19: =IF(ISTEXT(I19:I153), VLOOKUP(J19:J153,INDIRECT(I19:I153),K19:K153,0), ) -> Collect 400 Hearts by 2/24 11:00 PM PST for this! | M19: OK | N19: IW | O19: Bill | P19: 46064 | V19: 2026/2/9 驗證單配置資料與後台不符，驗證單資料時間錯誤
A20: =ROW()-2 -> 18 | D20: サムネイル画像が表示されているか | G20: 是否正常顯示縮圖 | L20: =IF(ISTEXT(I20:I154), VLOOKUP(J20:J154,INDIRECT(I20:I154),K20:K154,0), ) | M20: OK | N20: IW | O20: Bill | P20: 46064 | Q20: OK | R20: IW | S20: Bill | T20: 2/12
A21: =ROW()-2 -> 19 | B21: ='参照_各種特典'!C18&" "&'参照_各種特典'!D18 -> 早期全コレクション特典 Early Clear Bonus Platinum | C21: コレクションイベント＞該当イベント＞各種特典 | D21: 開始日時が右記の通り設定されているか | E21: ='参照_各種特典'!C18&" "&'参照_各種特典'!D18 -> 早期全コレクション特典 Early Clear Bonus Platinum | F21: 收集活動＞該活動＞各種特典 | G21: 開始日期時間是否按右側設定 | H21: ='参照_各種特典'!I18 -> 46074.708 | I21: BonusGroup!B5:J | J21: ce_203_bonus_group_004 | K21: 6 | L21: =IF(ISTEXT(I21:I155), VLOOKUP(J21:J155,INDIRECT(I21:I155),K21:K155,0), ) -> 46074.708 | M21: OK | N21: IW | O21: Bill | P21: 46062
A22: =ROW()-2 -> 20 | D22: 終了日時が右記の通り設定されているか | G22: 結束日期時間是否按右側設定 | H22: ='参照_各種特典'!J18 -> 46078.958 | I22: BonusGroup!B5:J | J22: ce_203_bonus_group_004 | K22: 7 | L22: =IF(ISTEXT(I22:I156), VLOOKUP(J22:J156,INDIRECT(I22:I156),K22:K156,0), ) -> 46078.958 | M22: OK | N22: IW | O22: Bill | P22: 46063 | V22: 2026/2/9 驗證單配置資料與後台不符
A23: =ROW()-2 -> 21 | D23: 特典内容が右記の通り設定されているか | G23: 特典內容是否按右側設定 | H23: ='参照_各種特典'!F18 -> The Forest Where Spirits Dwell | I23: Bonus!A5:L | J23: ce_203_bonus_group_004 | K23: 6 | L23: =IF(ISTEXT(I23:I157), VLOOKUP(J23:J157,INDIRECT(I23:I157),K23:K157,0), ) -> The Forest Where Spirits Dwell | M23: OK | N23: IW | O23: Bill | P23: 46063 | V23: 2026/2/9 驗證單配置資料與後台不符
A24: =ROW()-2 -> 22 | C24: コレクションイベント＞該当イベント＞エンジン設定＞EARLY_BONUS_ALL_COLLECTION値 | D24: 取得条件の数値が右記の通り設定されているか | F24: 收集活動＞該活動＞引擎設定＞EARLY_BONUS_ALL_COLLECTION値 | G24: 取得條件的數值是否按右側設定 | H24: 560 | I24: BonusGroup!B5:J | J24: ce_203_bonus_group_004 | K24: 9 | L24: =IF(ISTEXT(I24:I158), VLOOKUP(J24:J158,INDIRECT(I24:I158),K24:K158,0), ) -> 560 | M24: OK | N24: IW | O24: Bill | P24: 46062 | U24: IDの数値が大きい方が採用される
A25: =ROW()-2 -> 23 | C25: 実機 | D25: 特典一覧にてモーダル内の特典内容が右記の通り表示されているか | F25: 實體機台 | G25: 特典一覽中的彈窗內特典內容是否按右側顯示 | H25: ='参照_各種特典'!G19 -> Collect 560 Hearts by 2/25 11:00 PM PST for this! | I25: BonusGroup!B5:J | J25: ce_203_bonus_group_004 | K25: 5 | L25: =IF(ISTEXT(I25:I159), VLOOKUP(J25:J159,INDIRECT(I25:I159),K25:K159,0), ) -> Collect 560 Hearts by 2/25 11:00 PM PST for this! | M25: OK | N25: IW | O25: Bill | P25: 46064 | V25: 2026/2/9 驗證單配置資料與後台不符
A26: =ROW()-2 -> 24 | D26: サムネイル画像が表示されているか | G26: 是否正常顯示縮圖 | L26: =IF(ISTEXT(I26:I160), VLOOKUP(J26:J160,INDIRECT(I26:I160),K26:K160,0), ) | M26: OK | N26: IW | O26: Bill | P26: 46064 | Q26: OK | R26: IW | S26: Bill | T26: 2/12
A27: =ROW()-2 -> 25 | B27: Bonus Stories | C27: 実機 | D27: 特典内容が右記の通り表示されているか | E27: "Bonus Storiesと Special Colletion Bonuses内のストーリー ※故事名稱在「Bonus Stories」看不到，所以請大致確認圖片人物等有符合即可。而故事名稱會出現在「Collection Bonus」&「Special Collection Bonus」，出現在該處時須確認 | F27: 實體機台 | G27: 特典內容是否按右側設定 | H27: ='参照_仕様'!C11 -> Mystic Matrimony Bonus Story ～Masamune～ | I27: Bonus!J5:L | J27: 6314 | K27: 2 | L27: =IF(ISTEXT(I27:I161), VLOOKUP(J27:J161,INDIRECT(I27:I161),K27:K161,0), ) -> Mystic Matrimony Bonus Story ～Masamune～ | M27: OK | N27: IW | O27: Bill | P27: 46062
A28: =ROW()-2 -> 26 | D28: 訴求バナー画像が表示されているか | G28: 是否顯示宣傳橫幅圖片 | L28: =IF(ISTEXT(I28:I162), VLOOKUP(J28:J162,INDIRECT(I28:I162),K28:K162,0), ) | M28: OK | N28: IW | O28: Bill | P28: 46064 | Q28: OK | R28: IW | S28: Bill | T28: 2/12
A29: =ROW()-2 -> 27 | D29: サムネイル画像が表示されているか | G29: 是否正常顯示縮圖 | L29: =IF(ISTEXT(I29:I163), VLOOKUP(J29:J163,INDIRECT(I29:I163),K29:K163,0), ) | M29: OK | N29: IW | O29: Bill | P29: 46064 | Q29: OK | R29: IW | S29: Bill | T29: 2/12
A30: =ROW()-2 -> 28 | C30: 実機 | D30: 特典内容が右記の通り表示されているか | F30: 實體機台 | G30: 特典內容是否按右側設定 | H30: ='参照_仕様'!C12 -> Mystic Matrimony Bonus Story ～Nobunaga～ | I30: Bonus!J5:L | J30: 6315 | K30: 2 | L30: =IF(ISTEXT(I30:I164), VLOOKUP(J30:J164,INDIRECT(I30:I164),K30:K164,0), ) -> Mystic Matrimony Bonus Story ～Nobunaga～ | M30: OK | N30: IW | O30: Bill | P30: 46062
A31: =ROW()-2 -> 29 | D31: 訴求バナー画像が表示されているか | G31: 是否顯示宣傳橫幅圖片 | L31: =IF(ISTEXT(I31:I165), VLOOKUP(J31:J165,INDIRECT(I31:I165),K31:K165,0), ) | M31: OK | N31: IW | O31: Bill | P31: 46064 | Q31: OK | R31: IW | S31: Bill | T31: 2/12
A32: =ROW()-2 -> 30 | D32: サムネイル画像が表示されているか | G32: 是否正常顯示縮圖 | L32: =IF(ISTEXT(I32:I166), VLOOKUP(J32:J166,INDIRECT(I32:I166),K32:K166,0), ) | M32: OK | N32: IW | O32: Bill | P32: 46064 | Q32: OK | R32: IW | S32: Bill | T32: 2/12
A33: =ROW()-2 -> 31 | C33: 実機 | D33: 特典内容が右記の通り表示されているか | F33: 實體機台 | G33: 特典內容是否按右側設定 | H33: ='参照_仕様'!C13 -> Mystic Matrimony Bonus Story ～Kanetsugu～ | I33: Bonus!J5:L | J33: 6316 | K33: 2 | L33: =IF(ISTEXT(I33:I167), VLOOKUP(J33:J167,INDIRECT(I33:I167),K33:K167,0), ) -> Mystic Matrimony Bonus Story ～Kanetsugu～ | M33: OK | N33: IW | O33: Bill | P33: 46062
A34: =ROW()-2 -> 32 | D34: 訴求バナー画像が表示されているか | G34: 是否顯示宣傳橫幅圖片 | L34: =IF(ISTEXT(I34:I168), VLOOKUP(J34:J168,INDIRECT(I34:I168),K34:K168,0), ) | M34: OK | N34: IW | O34: Bill | P34: 46064 | Q34: OK | R34: IW | S34: Bill | T34: 2/12
A35: =ROW()-2 -> 33 | D35: サムネイル画像が表示されているか | G35: 是否正常顯示縮圖 | L35: =IF(ISTEXT(I35:I169), VLOOKUP(J35:J169,INDIRECT(I35:I169),K35:K169,0), ) | M35: OK | N35: IW | O35: Bill | P35: 46064 | Q35: OK | R35: IW | S35: Bill | T35: 2/12
A36: =ROW()-2 -> 34 | C36: 実機 | D36: 特典内容が右記の通り表示されているか | F36: 實體機台 | G36: 特典內容是否按右側設定 | H36: ='参照_仕様'!C14 -> Mystic Matrimony Bonus Story ～Kicho～ | I36: Bonus!J5:L | J36: 6317 | K36: 2 | L36: =IF(ISTEXT(I36:I170), VLOOKUP(J36:J170,INDIRECT(I36:I170),K36:K170,0), ) -> Mystic Matrimony Bonus Story ～Kicho～ | M36: OK | N36: IW | O36: Bill | P36: 46062
A37: =ROW()-2 -> 35 | D37: 訴求バナー画像が表示されているか | G37: 是否顯示宣傳橫幅圖片 | L37: =IF(ISTEXT(I37:I171), VLOOKUP(J37:J171,INDIRECT(I37:I171),K37:K171,0), ) | M37: OK | N37: IW | O37: Bill | P37: 46064 | Q37: OK | R37: IW | S37: Bill | T37: 2/12
A38: =ROW()-2 -> 36 | D38: サムネイル画像が表示されているか | G38: 是否正常顯示縮圖 | L38: =IF(ISTEXT(I38:I172), VLOOKUP(J38:J172,INDIRECT(I38:I172),K38:K172,0), ) | M38: OK | N38: IW | O38: Bill | P38: 46064 | Q38: OK | R38: IW | S38: Bill | T38: 2/12
A39: =ROW()-2 -> 37 | C39: 実機 | D39: 特典内容が右記の通り表示されているか | F39: 實體機台 | G39: 特典內容是否按右側設定 | H39: ='参照_仕様'!C15 -> Mystic Matrimony Bonus Story ～Motonari～ | I39: Bonus!J5:L | J39: 6318 | K39: 2 | L39: =IF(ISTEXT(I39:I173), VLOOKUP(J39:J173,INDIRECT(I39:I173),K39:K173,0), ) -> Mystic Matrimony Bonus Story ～Motonari～ | M39: OK | N39: IW | O39: Bill | P39: 46062
A40: =ROW()-2 -> 38 | D40: 訴求バナー画像が表示されているか | G40: 是否顯示宣傳橫幅圖片 | L40: =IF(ISTEXT(I40:I174), VLOOKUP(J40:J174,INDIRECT(I40:I174),K40:K174,0), ) | M40: OK | N40: IW | O40: Bill | P40: 46064 | Q40: OK | R40: IW | S40: Bill | T40: 2/12
...

Sheet BonusGroup
B1: https://common-legacy-app-admin.us.ikemen-sengoku.jp/admin/isgame/collection/all_setting/203#Bonus%20Group
B3: {=SEQUENCE(1,COLUMNS(B:M))} -> 1 | C3: 2 | D3: 3 | E3: 4 | F3: 5 | G3: 6 | H3: 7 | I3: 8 | J3: 9 | K3: 10 | L3: 11 | M3: 12
A4: ID | B4: bonus group cd | C4: collect event cd | D4: bonus group type | E4: group name | F4: description | G4: get bonus start | H4: get bonus end | I4: bonus time limit | J4: collect item get count | K4: order | L4: update | M4: resource generated
A5: 5404 | B5: ce_203_bonus_group_001 | C5: collect_203 | D5: early_gold | E5: Early Clear Bonus Gold | F5: Collect 140 Hearts by 2/22 11:00 PM PST for this! | G5: 46074.708 | H5: 46075.958 | J5: 140 | K5: 1 | L5: 46058.267 | M5: 46058.267
A6: 5405 | B6: ce_203_bonus_group_002 | C6: collect_203 | D6: early_silver | E6: Early Clear Bonus Silver | F6: Collect 240 Hearts by 2/23 11:00 PM PST for this! | G6: 46074.708 | H6: 46076.958 | J6: 240 | K6: 2 | L6: 46058.267 | M6: 46058.267
A7: 5406 | B7: ce_203_bonus_group_003 | C7: collect_203 | D7: early_copper | E7: Early Clear Bonus Mystic Matrimony | F7: Collect 400 Hearts by 2/24 11:00 PM PST for this! | G7: 46074.708 | H7: 46077.958 | J7: 400 | K7: 3 | L7: 46058.267 | M7: 46058.267
A8: 5407 | B8: ce_203_bonus_group_004 | C8: collect_203 | D8: early_all_collection | E8: Early Clear Bonus Platinum | F8: Collect 560 Hearts by 2/25 11:00 PM PST for this! | G8: 46074.708 | H8: 46078.958 | J8: 560 | K8: 4 | L8: 46058.267 | M8: 46058.267
A9: 5408 | B9: ce_203_bonus_group_005 | C9: collect_203 | D9: story | E9: Bonus Stories | F9: Collect Hearts to get Bonus Stories! | G9: 0 | H9: 0 | J9: 0 | K9: 5 | L9: 46058.267 | M9: 46058.267
A10: 5409 | B10: ce_203_bonus_group_007 | C10: collect_203 | D10: collection | E10: Collection Bonuses | F10: Collect Hearts & get great Attire & Avatars! | G10: 0 | H10: 0 | J10: 0 | K10: 7 | L10: 46058.267 | M10: 46058.267
A11: 5411 | B11: ce_203_bonus_group_009 | C11: collect_203 | D11: special_collection | E11: Special Collection Bonus | F11: Collect Hearts to get Bonus! | G11: 0 | H11: 0 | J11: 600 | K11: 9 | L11: 46058.267 | M11: 46058.267
A12: 5413 | B12: ce_203_bonus_group_011 | C12: collect_203 | D12: special_collection | E12: Special Collection Bonus | F12: Collect Hearts to get Bonus! | G12: 0 | H12: 0 | J12: 650 | K12: 12 | L12: 46058.267 | M12: 46058.267
A13: 5415 | B13: ce_203_bonus_group_013 | C13: collect_203 | D13: special_collection | E13: Special Collection Bonus | F13: Collect Hearts to get Bonus! | G13: 0 | H13: 0 | J13: 700 | K13: 14 | L13: 46058.267 | M13: 46058.267
A14: 5417 | B14: ce_203_bonus_group_015 | C14: collect_203 | D14: special_collection | E14: Special Collection Bonus | F14: Collect Hearts to get Bonus! | G14: 0 | H14: 0 | J14: 750 | K14: 17 | L14: 46058.267 | M14: 46058.267
A15: 5419 | B15: ce_203_bonus_group_017 | C15: collect_203 | D15: special_collection | E15: Special Collection Bonus | F15: Collect Hearts to get Bonus! | G15: 0 | H15: 0 | J15: 800 | K15: 19 | L15: 46058.267 | M15: 46058.267
A16: 5421 | B16: ce_203_bonus_group_019 | C16: collect_203 | D16: special_collection | E16: Special Collection Bonus | F16: Collect Hearts to get Bonus! | G16: 0 | H16: 0 | J16: 850 | K16: 23 | L16: 46058.267 | M16: 46058.267
... A19: 5426 | B19: ce_203_bonus_group_024 | C19: collect_203 | D19: last_ranking | E19: Final Ranking Bonuses | F19: Rank in for these! | G19: 0 | H19: 0 | J19: 0 | K19: 34 | L19: 46058.267 | M19: 46058.267
A20: 5427 | B20: ce_203_bonus_group_025 | C20: collect_203 | D20: linked | E20: Extra Bonus | G20: 0 | H20: 0 | J20: 500 | K20: 35 | L20: 46058.267 | M20: 46058.267

Sheet Bonus
A1: https://common-legacy-app-admin.us.ikemen-sengoku.jp/admin/isgame/collection/all_setting/203#Bonus
J2: {=SEQUENCE(1,COLUMNS(J:M))} -> 1 | K2: 2 | L2: 3 | M2: 4 | S2: {=SEQUENCE(1,COLUMNS(S:V))} -> 1 | T2: 2 | U2: 3 | V2: 4
A3: {=SEQUENCE(1,COLUMNS(A:V))} -> 1 | B3: 2 | C3: 3 | D3: 4 | E3: 5 | F3: 6 | G3: 7 | H3: 8 | I3: 9 | J3: 10 | K3: 11 | L3: 12 | M3: 13 | N3: 14 | O3: 15 | P3: 16 | Q3: 17 | R3: 18 | S3: 19 | T3: 20 | U3: 21 | V3: 22
A4: bonus group cd | B4: present | C4: present ID | D4: present Name / present descirption | E4: present Item with Count | F4: present Item | G4: present item count | H4: present description | I4: special story | J4: story ID | K4: story Name | L4: voice | M4: still | N4: order | O4: touch chara id | P4: vote group id | Q4: update | R4: All Bonus Combine Info
A5: ce_203_bonus_group_001 | B5: 171901▸Mystic Matrimony Early Clear Bonus Gold 〈Blue Anemone Hair Clip x 1〉 | C5: =IFERROR(__xludf.DUMMYFUNCTION("ARRAYFORMULA(IF(ISTEXT(B5:B47),SPLIT(B5:B47,""▸〈〉""),))"),171901.0) -> 171901 | D5: =IFERROR(__xludf.DUMMYFUNCTION("""COMPUTED_VALUE"""),"Mystic Matrimony Early Clear Bonus Gold ") -> Mystic Matrimony Early Clear Bonus Gold | E5: =IFERROR(__xludf.DUMMYFUNCTION("""COMPUTED_VALUE"""),"Blue Anemone Hair Clip x 1") -> Blue Anemone Hair Clip x 1 | F5: {=if(ISTEXT(E5:E47), LEFT(E5:E47,LEN(E5:E47)-4), )} -> Blue Anemone Hair Clip | G5: 1 | H5: Mystic Matrimony Early Clear Bonus Gold | J5: =IFERROR(__xludf.DUMMYFUNCTION("ARRAYFORMULA(IF(ISTEXT(I5:I47),SPLIT(I5:I47,""▸""),))"),"") | N5: 1 | Q5: 46058.272 | R5: {=LET( _present, B5:B47, _special_story, I5:I47, _voice, L5:L47, _still, M5:M47, IFS( LEN(_present),_present, LEN(_special_story),_special_story, LEN(_voice),_voice, LEN(_still),_still) )} -> 171901▸Mystic Matrimony Early Clear Bonus Gold 〈Blue Anemone Hair Clip x 1〉 | S5: =IFERROR(__xludf.DUMMYFUNCTION("ARRAYFORMULA(IF(ISTEXT(R5:R47),SPLIT(R5:R47,""▸〈〉""),))"),171901.0) -> 171901 | T5: =IFERROR(__xludf.DUMMYFUNCTION("""COMPUTED_VALUE"""),"Mystic Matrimony Early Clear Bonus Gold ") -> Mystic Matrimony Early Clear Bonus Gold | U5: =IFERROR(__xludf.DUMMYFUNCTION("""COMPUTED_VALUE"""),"Blue Anemone Hair Clip x 1") -> Blue Anemone Hair Clip x 1 | V5: {=if(ISTEXT(U5:U47), LEFT(U5:U47,LEN(U5:U47)-4), )} -> Blue Anemone Hair Clip
A6: ce_203_bonus_group_002 | B6: 171902▸Mystic Matrimony Early Clear Bonus Silver 〈Shining Silver Ash Hair x 1〉 | C6: =IFERROR(__xludf.DUMMYFUNCTION("""COMPUTED_VALUE"""),171902.0) -> 171902 | D6: =IFERROR(__xludf.DUMMYFUNCTION("""COMPUTED_VALUE"""),"Mystic Matrimony Early Clear Bonus Silver ") -> Mystic Matrimony Early Clear Bonus Silver | E6: =IFERROR(__xludf.DUMMYFUNCTION("""COMPUTED_VALUE"""),"Shining Silver Ash Hair x 1") -> Shining Silver Ash Hair x 1 | F6: Shining Silver Ash Hair | G6: 1 | H6: Mystic Matrimony Early Clear Bonus Silver | N6: 1 | Q6: 46058.272 | R6: 171902▸Mystic Matrimony Early Clear Bonus Silver 〈Shining Silver Ash Hair x 1〉 | S6: =IFERROR(__xludf.DUMMYFUNCTION("""COMPUTED_VALUE"""),171902.0) -> 171902 | T6: =IFERROR(__xludf.DUMMYFUNCTION("""COMPUTED_VALUE"""),"Mystic Matrimony Early Clear Bonus Silver ") -> Mystic Matrimony Early Clear Bonus Silver | U6: =IFERROR(__xludf.DUMMYFUNCTION("""COMPUTED_VALUE"""),"Shining Silver Ash Hair x 1") -> Shining Silver Ash Hair x 1 | V6: Shining Silver Ash Hair
A7: ce_203_bonus_group_003 | B7: 171903▸Mystic Matrimony Early Clear Bonus Mystic Matrimony 〈Effect: Shiny White Spider Lily x 1〉 | C7: =IFERROR(__xludf.DUMMYFUNCTION("""COMPUTED_VALUE"""),171903.0) -> 171903 | D7: =IFERROR(__xludf.DUMMYFUNCTION("""COMPUTED_VALUE"""),"Mystic Matrimony Early Clear Bonus Mystic Matrimony ") -> Mystic Matrimony Early Clear Bonus Mystic Matrimony | E7: =IFERROR(__xludf.DUMMYFUNCTION("""COMPUTED_VALUE"""),"Effect: Shiny White Spider Lily x 1") -> Effect: Shiny White Spider Lily x 1 | F7: Effect: Shiny White Spider Lily | G7: 1 | H7: Mystic Matrimony Early Clear Bonus Mystic Matrimony | N7: 1 | Q7: 46058.272 | R7: 171903▸Mystic Matrimony Early Clear Bonus Mystic Matrimony 〈Effect: Shiny White Spider Lily x 1〉 | S7: =IFERROR(__xludf.DUMMYFUNCTION("""COMPUTED_VALUE"""),171903.0) -> 171903 | T7: =IFERROR(__xludf.DUMMYFUNCTION("""COMPUTED_VALUE"""),"Mystic Matrimony Early Clear Bonus Mystic Matrimony ") -> Mystic Matrimony Early Clear Bonus Mystic Matrimony | U7: =IFERROR(__xludf.DUMMYFUNCTION("""COMPUTED_VALUE"""),"Effect: Shiny White Spider Lily x 1") -> Effect: Shiny White Spider Lily x 1 | V7: Effect: Shiny White Spider Lily
A8: ce_203_bonus_group_004 | B8: 171904▸Mystic Matrimony Early Clear Bonus Platinum 〈The Forest Where Spirits Dwell x 1〉 | C8: =IFERROR(__xludf.DUMMYFUNCTION("""COMPUTED_VALUE"""),171904.0) -> 171904 | D8: =IFERROR(__xludf.DUMMYFUNCTION("""COMPUTED_VALUE"""),"Mystic Matrimony Early Clear Bonus Platinum ") -> Mystic Matrimony Early Clear Bonus Platinum | E8: =IFERROR(__xludf.DUMMYFUNCTION("""COMPUTED_VALUE"""),"The Forest Where Spirits Dwell x 1") -> The Forest Where Spirits Dwell x 1 | F8: The Forest Where Spirits Dwell | G8: 1 | H8: Mystic Matrimony Early Clear Bonus Platinum | N8: 1 | Q8: 46058.272 | R8: 171904▸Mystic Matrimony Early Clear Bonus Platinum 〈The Forest Where Spirits Dwell x 1〉 | S8: =IFERROR(__xludf.DUMMYFUNCTION("""COMPUTED_VALUE"""),171904.0) -> 171904 | T8: =IFERROR(__xludf.DUMMYFUNCTION("""COMPUTED_VALUE"""),"Mystic Matrimony Early Clear Bonus Platinum ") -> Mystic Matrimony Early Clear Bonus Platinum | U8: =IFERROR(__xludf.DUMMYFUNCTION("""COMPUTED_VALUE"""),"The Forest Where Spirits Dwell x 1") -> The Forest Where Spirits Dwell x 1 | V8: The Forest Where Spirits Dwell
A9: ce_203_bonus_group_005 | I9: 6313▸Demon of My Dreams | J9: =IFERROR(__xludf.DUMMYFUNCTION("""COMPUTED_VALUE"""),6313.0) -> 6313 | K9: =IFERROR(__xludf.DUMMYFUNCTION("""COMPUTED_VALUE"""),"Demon of My Dreams") -> Demon of My Dreams | N9: 1 | Q9: 46058.272 | R9: 6313▸Demon of My Dreams | S9: =IFERROR(__xludf.DUMMYFUNCTION("""COMPUTED_VALUE"""),6313.0) -> 6313 | T9: =IFERROR(__xludf.DUMMYFUNCTION("""COMPUTED_VALUE"""),"Demon of My Dreams") -> Demon of My Dreams
A10: ce_203_bonus_group_005 | I10: 6314▸Mystic Matrimony Bonus Story ～Masamune～ | J10: =IFERROR(__xludf.DUMMYFUNCTION("""COMPUTED_VALUE"""),6314.0) -> 6314 | K10: =IFERROR(__xludf.DUMMYFUNCTION("""COMPUTED_VALUE"""),"Mystic Matrimony Bonus Story ～Masamune～") -> Mystic Matrimony Bonus Story ～Masamune～ | N10: 1 | Q10: 46058.272 | R10: 6314▸Mystic Matrimony Bonus Story ～Masamune～ | S10: =IFERROR(__xludf.DUMMYFUNCTION("""COMPUTED_VALUE"""),6314.0) -> 6314 | T10: =IFERROR(__xludf.DUMMYFUNCTION("""COMPUTED_VALUE"""),"Mystic Matrimony Bonus Story ～Masamune～") -> Mystic Matrimony Bonus Story ～Masamune～
A11: ce_203_bonus_group_005 | I11: 6315▸Mystic Matrimony Bonus Story ～Nobunaga～ | J11: =IFERROR(__xludf.DUMMYFUNCTION("""COMPUTED_VALUE"""),6315.0) -> 6315 | K11: =IFERROR(__xludf.DUMMYFUNCTION("""COMPUTED_VALUE"""),"Mystic Matrimony Bonus Story ～Nobunaga～") -> Mystic Matrimony Bonus Story ～Nobunaga～ | N11: 1 | Q11: 46058.272 | R11: 6315▸Mystic Matrimony Bonus Story ～Nobunaga～ | S11: =IFERROR(__xludf.DUMMYFUNCTION("""COMPUTED_VALUE"""),6315.0) -> 6315 | T11: =IFERROR(__xludf.DUMMYFUNCTION("""COMPUTED_VALUE"""),"Mystic Matrimony Bonus Story ～Nobunaga～") -> Mystic Matrimony Bonus Story ～Nobunaga～
A12: ce_203_bonus_group_005 | I12: 6316▸Mystic Matrimony Bonus Story ～Kanetsugu～ | J12: =IFERROR(__xludf.DUMMYFUNCTION("""COMPUTED_VALUE"""),6316.0) -> 6316 | K12: =IFERROR(__xludf.DUMMYFUNCTION("""COMPUTED_VALUE"""),"Mystic Matrimony Bonus Story ～Kanetsugu～") -> Mystic Matrimony Bonus Story ～Kanetsugu～ | N12: 1 | Q12: 46058.272 | R12: 6316▸Mystic Matrimony Bonus Story ～Kanetsugu～ | S12: =IFERROR(__xludf.DUMMYFUNCTION("""COMPUTED_VALUE"""),6316.0) -> 6316 | T12: =IFERROR(__xludf.DUMMYFUNCTION("""COMPUTED_VALUE"""),"Mystic Matrimony Bonus Story ～Kanetsugu～") -> Mystic Matrimony Bonus Story ～Kanetsugu～
A13: ce_203_bonus_group_005 | I13: 6317▸Mystic Matrimony Bonus Story ～Kicho～ | J13: =IFERROR(__xludf.DUMMYFUNCTION("""COMPUTED_VALUE"""),6317.0) -> 6317 | K13: =IFERROR(__xludf.DUMMYFUNCTION("""COMPUTED_VALUE"""),"Mystic Matrimony Bonus Story ～Kicho～") -> Mystic Matrimony Bonus Story ～Kicho～ | N13: 1 | Q13: 46058.272 | R13: 6317▸Mystic Matrimony Bonus Story ～Kicho～ | S13: =IFERROR(__xludf.DUMMYFUNCTION("""COMPUTED_VALUE"""),6317.0) -> 6317 | T13: =IFERROR(__xludf.DUMMYFUNCTION("""COMPUTED_VALUE"""),"Mystic Matrimony Bonus Story ～Kicho～") -> Mystic Matrimony Bonus Story ～Kicho～
A14: ce_203_bonus_group_005 | I14: 6318▸Mystic Matrimony Bonus Story ～Motonari～ | J14: =IFERROR(__xludf.DUMMYFUNCTION("""COMPUTED_VALUE"""),6318.0) -> 6318 | K14: =IFERROR(__xludf.DUMMYFUNCTION("""COMPUTED_VALUE"""),"Mystic Matrimony Bonus Story ～Motonari～") -> Mystic Matrimony Bonus Story ～Motonari～ | N14: 1 | Q14: 46058.272 | R14: 6318▸Mystic Matrimony Bonus Story ～Motonari～ | S14: =IFERROR(__xludf.DUMMYFUNCTION("""COMPUTED_VALUE"""),6318.0) -> 6318 | T14: =IFERROR(__xludf.DUMMYFUNCTION("""COMPUTED_VALUE"""),"Mystic Matrimony Bonus Story ～Motonari～") -> Mystic Matrimony Bonus Story ～Motonari～
A15: ce_203_bonus_group_005 | I15: 6319▸Mystic Matrimony Bonus Story ～Yoshimoto～ | J15: =IFERROR(__xludf.DUMMYFUNCTION("""COMPUTED_VALUE"""),6319.0) -> 6319 | K15: =IFERROR(__xludf.DUMMYFUNCTION("""COMPUTED_VALUE"""),"Mystic Matrimony Bonus Story ～Yoshimoto～") -> Mystic Matrimony Bonus Story ～Yoshimoto～ | N15: 1 | Q15: 46058.272 | R15: 6319▸Mystic Matrimony Bonus Story ～Yoshimoto～ | S15: =IFERROR(__xludf.DUMMYFUNCTION("""COMPUTED_VALUE"""),6319.0) -> 6319 | T15: =IFERROR(__xludf.DUMMYFUNCTION("""COMPUTED_VALUE"""),"Mystic Matrimony Bonus Story ～Yoshimoto～") -> Mystic Matrimony Bonus Story ～Yoshimoto～
A16: ce_203_bonus_group_007 | M16: 3780▸Mystic Matrimony ~Yoshimoto~ | N16: 1 | Q16: 46058.272 | R16: 3780▸Mystic Matrimony ~Yoshimoto~ | S16: =IFERROR(__xludf.DUMMYFUNCTION("""COMPUTED_VALUE"""),3780.0) -> 3780 | T16: =IFERROR(__xludf.DUMMYFUNCTION("""COMPUTED_VALUE"""),"Mystic Matrimony ~Yoshimoto~") -> Mystic Matrimony ~Yoshimoto~
A17: ce_203_bonus_group_009 | M17: 3779▸Mystic Matrimony ~Motonari~ | N17: 1 | Q17: 46058.272 | R17: 3779▸Mystic Matrimony ~Motonari~ | S17: =IFERROR(__xludf.DUMMYFUNCTION("""COMPUTED_VALUE"""),3779.0) -> 3779 | T17: =IFERROR(__xludf.DUMMYFUNCTION("""COMPUTED_VALUE"""),"Mystic Matrimony ~Motonari~") -> Mystic Matrimony ~Motonari~
A18: ce_203_bonus_group_009 | B18: 171906▸Mystic Matrimony Special Collection Bonus 〈Mystic Matrimony Yoshimoto x 1〉 | C18: =IFERROR(__xludf.DUMMYFUNCTION("""COMPUTED_VALUE"""),171906.0) -> 171906 | D18: =IFERROR(__xludf.DUMMYFUNCTION("""COMPUTED_VALUE"""),"Mystic Matrimony Special Collection Bonus ") -> Mystic Matrimony Special Collection Bonus | E18: =IFERROR(__xludf.DUMMYFUNCTION("""COMPUTED_VALUE"""),"Mystic Matrimony Yoshimoto x 1") -> Mystic Matrimony Yoshimoto x 1 | F18: Mystic Matrimony Yoshimoto | G18: 1 | H18: Mystic Matrimony Special Collection Bonus | N18: 1 | Q18: 46058.272 | R18: 171906▸Mystic Matrimony Special Collection Bonus 〈Mystic Matrimony Yoshimoto x 1〉 | S18: =IFERROR(__xludf.DUMMYFUNCTION("""COMPUTED_VALUE"""),171906.0) -> 171906 | T18: =IFERROR(__xludf.DUMMYFUNCTION("""COMPUTED_VALUE"""),"Mystic Matrimony Special Collection Bonus ") -> Mystic Matrimony Special Collection Bonus | U18: =IFERROR(__xludf.DUMMYFUNCTION("""COMPUTED_VALUE"""),"Mystic Matrimony Yoshimoto x 1") -> Mystic Matrimony Yoshimoto x 1 | V18: Mystic Matrimony Yoshimoto
A19: ce_203_bonus_group_011 | I19: 6325▸Mystic Matrimony After Story ～Yoshimoto～ | J19: =IFERROR(__xludf.DUMMYFUNCTION("""COMPUTED_VALUE"""),6325.0) -> 6325 | K19: =IFERROR(__xludf.DUMMYFUNCTION("""COMPUTED_VALUE"""),"Mystic Matrimony After Story ～Yoshimoto～") -> Mystic Matrimony After Story ～Yoshimoto～ | N19: 1 | Q19: 46058.272 | R19: 6325▸Mystic Matrimony After Story ～Yoshimoto～ | S19: =IFERROR(__xludf.DUMMYFUNCTION("""COMPUTED_VALUE"""),6325.0) -> 6325 | T19: =IFERROR(__xludf.DUMMYFUNCTION("""COMPUTED_VALUE"""),"Mystic Matrimony After Story ～Yoshimoto～") -> Mystic Matrimony After Story ～Yoshimoto～
A20: ce_203_bonus_group_013 | M20: 3778▸Mystic Matrimony ~Kicho~ | N20: 1 | Q20: 46058.272 | R20: 3778▸Mystic Matrimony ~Kicho~ | S20: =IFERROR(__xludf.DUMMYFUNCTION("""COMPUTED_VALUE"""),3778.0) -> 3778 | T20: =IFERROR(__xludf.DUMMYFUNCTION("""COMPUTED_VALUE"""),"Mystic Matrimony ~Kicho~") -> Mystic Matrimony ~Kicho~
A21: ce_203_bonus_group_013 | B21: 171909▸Mystic Matrimony Special Collection Bonus 〈Mystic Matrimony Motonari x 1〉 | C21: =IFERROR(__xludf.DUMMYFUNCTION("""COMPUTED_VALUE"""),171909.0) -> 171909 | D21: =IFERROR(__xludf.DUMMYFUNCTION("""COMPUTED_VALUE"""),"Mystic Matrimony Special Collection Bonus ") -> Mystic Matrimony Special Collection Bonus | E21: =IFERROR(__xludf.DUMMYFUNCTION("""COMPUTED_VALUE"""),"Mystic Matrimony Motonari x 1") -> Mystic Matrimony Motonari x 1 | F21: Mystic Matrimony Motonari | G21: 1 | H21: Mystic Matrimony Special Collection Bonus | N21: 1 | Q21: 46058.272 | R21: 171909▸Mystic Matrimony Special Collection Bonus 〈Mystic Matrimony Motonari x 1〉 | S21: =IFERROR(__xludf.DUMMYFUNCTION("""COMPUTED_VALUE"""),171909.0) -> 171909 | T21: =IFERROR(__xludf.DUMMYFUNCTION("""COMPUTED_VALUE"""),"Mystic Matrimony Special Collection Bonus ") -> Mystic Matrimony Special Collection Bonus | U21: =IFERROR(__xludf.DUMMYFUNCTION("""COMPUTED_VALUE"""),"Mystic Matrimony Motonari x 1") -> Mystic Matrimony Motonari x 1 | V21: Mystic Matrimony Motonari
A22: ce_203_bonus_group_015 | I22: 6324▸Mystic Matrimony After Story ～Motonari～ | J22: =IFERROR(__xludf.DUMMYFUNCTION("""COMPUTED_VALUE"""),6324.0) -> 6324 | K22: =IFERROR(__xludf.DUMMYFUNCTION("""COMPUTED_VALUE"""),"Mystic Matrimony After Story ～Motonari～") -> Mystic Matrimony After Story ～Motonari～ | N22: 1 | Q22: 46058.272 | R22: 6324▸Mystic Matrimony After Story ～Motonari～ | S22: =IFERROR(__xludf.DUMMYFUNCTION("""COMPUTED_VALUE"""),6324.0) -> 6324 | T22: =IFERROR(__xludf.DUMMYFUNCTION("""COMPUTED_VALUE"""),"Mystic Matrimony After Story ～Motonari～") -> Mystic Matrimony After Story ～Motonari～
A23: ce_203_bonus_group_017 | I23: 6323▸Mystic Matrimony After Story ～Kicho～ | J23: =IFERROR(__xludf.DUMMYFUNCTION("""COMPUTED_VALUE"""),6323.0) -> 6323 | K23: =IFERROR(__xludf.DUMMYFUNCTION("""COMPUTED_VALUE"""),"Mystic Matrimony After Story ～Kicho～") -> Mystic Matrimony After Story ～Kicho～ | N23: 1 | Q23: 46058.272 | R23: 6323▸Mystic Matrimony After Story ～Kicho～ | S23: =IFERROR(__xludf.DUMMYFUNCTION("""COMPUTED_VALUE"""),6323.0) -> 6323 | T23: =IFERROR(__xludf.DUMMYFUNCTION("""COMPUTED_VALUE"""),"Mystic Matrimony After Story ～Kicho～") -> Mystic Matrimony After Story ～Kicho～
A24: ce_203_bonus_group_017 | M24: 3777▸Mystic Matrimony ~Kanetsugu~ | N24: 1 | Q24: 46058.272 | R24: 3777▸Mystic Matrimony ~Kanetsugu~ | S24: =IFERROR(__xludf.DUMMYFUNCTION("""COMPUTED_VALUE"""),3777.0) -> 3777 | T24: =IFERROR(__xludf.DUMMYFUNCTION("""COMPUTED_VALUE"""),"Mystic Matrimony ~Kanetsugu~") -> Mystic Matrimony ~Kanetsugu~
A25: ce_203_bonus_group_017 | B25: 171912▸Mystic Matrimony Special Collection Bonus 〈Mystic Matrimony Kicho x 1〉 | C25: =IFERROR(__xludf.DUMMYFUNCTION("""COMPUTED_VALUE"""),171912.0) -> 171912 | D25: =IFERROR(__xludf.DUMMYFUNCTION("""COMPUTED_VALUE"""),"Mystic Matrimony Special Collection Bonus ") -> Mystic Matrimony Special Collection Bonus | E25: =IFERROR(__xludf.DUMMYFUNCTION("""COMPUTED_VALUE"""),"Mystic Matrimony Kicho x 1") -> Mystic Matrimony Kicho x 1 | F25: Mystic Matrimony Kicho | G25: 1 | H25: Mystic Matrimony Special Collection Bonus | N25: 1 | Q25: 46058.272 | R25: 171912▸Mystic Matrimony Special Collection Bonus 〈Mystic Matrimony Kicho x 1〉 | S25: =IFERROR(__xludf.DUMMYFUNCTION("""COMPUTED_VALUE"""),171912.0) -> 171912 | T25: =IFERROR(__xludf.DUMMYFUNCTION("""COMPUTED_VALUE"""),"Mystic Matrimony Special Collection Bonus ") -> Mystic Matrimony Special Collection Bonus | U25: =IFERROR(__xludf.DUMMYFUNCTION("""COMPUTED_VALUE"""),"Mystic Matrimony Kicho x 1") -> Mystic Matrimony Kicho x 1 | V25: Mystic Matrimony Kicho
A26: ce_203_bonus_group_019 | I26: 6322▸Mystic Matrimony After Story ～Kanetsugu～ | J26: =IFERROR(__xludf.DUMMYFUNCTION("""COMPUTED_VALUE"""),6322.0) -> 6322 | K26: =IFERROR(__xludf.DUMMYFUNCTION("""COMPUTED_VALUE"""),"Mystic Matrimony After Story ～Kanetsugu～") -> Mystic Matrimony After Story ～Kanetsugu～ | N26: 1 | Q26: 46058.272 | R26: 6322▸Mystic Matrimony After Story ～Kanetsugu～ | S26: =IFERROR(__xludf.DUMMYFUNCTION("""COMPUTED_VALUE"""),6322.0) -> 6322 | T26: =IFERROR(__xludf.DUMMYFUNCTION("""COMPUTED_VALUE"""),"Mystic Matrimony After Story ～Kanetsugu～") -> Mystic Matrimony After Story ～Kanetsugu～
A27: ce_203_bonus_group_019 | M27: 3776▸Mystic Matrimony ~Nobunaga~ | N27: 1 | Q27: 46058.272 | R27: 3776▸Mystic Matrimony ~Nobunaga~ | S27: =IFERROR(__xludf.DUMMYFUNCTION("""COMPUTED_VALUE"""),3776.0) -> 3776 | T27: =IFERROR(__xludf.DUMMYFUNCTION("""COMPUTED_VALUE"""),"Mystic Matrimony ~Nobunaga~") -> Mystic Matrimony ~Nobunaga~
A28: ce_203_bonus_group_019 | B28: 171914▸Mystic Matrimony Special Collection Bonus 〈Mystic Matrimony Kanetsugu x 1〉 | C28: =IFERROR(__xludf.DUMMYFUNCTION("""COMPUTED_VALUE"""),171914.0) -> 171914 | D28: =IFERROR(__xludf.DUMMYFUNCTION("""COMPUTED_VALUE"""),"Mystic Matrimony Special Collection Bonus ") -> Mystic Matrimony Special Collection Bonus | E28: =IFERROR(__xludf.DUMMYFUNCTION("""COMPUTED_VALUE"""),"Mystic Matrimony Kanetsugu x 1") -> Mystic Matrimony Kanetsugu x 1 | F28: Mystic Matrimony Kanetsugu | G28: 1 | H28: Mystic Matrimony Special Collection Bonus | N28: 1 | Q28: 46058.272 | R28: 171914▸Mystic Matrimony Special Collection Bonus 〈Mystic Matrimony Kanetsugu x 1〉 | S28: =IFERROR(__xludf.DUMMYFUNCTION("""COMPUTED_VALUE"""),171914.0) -> 171914 | T28: =IFERROR(__xludf.DUMMYFUNCTION("""COMPUTED_VALUE"""),"Mystic Matrimony Special Collection Bonus ") -> Mystic Matrimony Special Collection Bonus | U28: =IFERROR(__xludf.DUMMYFUNCTION("""COMPUTED_VALUE"""),"Mystic Matrimony Kanetsugu x 1") -> Mystic Matrimony Kanetsugu x 1 | V28: Mystic Matrimony Kanetsugu
A29: ce_203_bonus_group_021 | I29: 6321▸Mystic Matrimony After Story ～Nobunaga～ | J29: =IFERROR(__xludf.DUMMYFUNCTION("""COMPUTED_VALUE"""),6321.0) -> 6321 | K29: =IFERROR(__xludf.DUMMYFUNCTION("""COMPUTED_VALUE"""),"Mystic Matrimony After Story ～Nobunaga～") -> Mystic Matrimony After Story ～Nobunaga～ | N29: 1 | Q29: 46058.272 | R29: 6321▸Mystic Matrimony After Story ～Nobunaga～ | S29: =IFERROR(__xludf.DUMMYFUNCTION("""COMPUTED_VALUE"""),6321.0) -> 6321 | T29: =IFERROR(__xludf.DUMMYFUNCTION("""COMPUTED_VALUE"""),"Mystic Matrimony After Story ～Nobunaga～") -> Mystic Matrimony After Story ～Nobunaga～
A30: ce_203_bonus_group_021 | M30: 3775▸Mystic Matrimony ~Masamune~ | N30: 1 | Q30: 46059.272 | R30: 3775▸Mystic Matrimony ~Masamune~ | S30: =IFERROR(__xludf.DUMMYFUNCTION("""COMPUTED_VALUE"""),3775.0) -> 3775 | T30: =IFERROR(__xludf.DUMMYFUNCTION("""COMPUTED_VALUE"""),"Mystic Matrimony ~Masamune~") -> Mystic Matrimony ~Masamune~
A31: ce_203_bonus_group_021 | B31: 171916▸Mystic Matrimony Special Collection Bonus 〈Mystic Matrimony Nobunaga x 1〉 | C31: =IFERROR(__xludf.DUMMYFUNCTION("""COMPUTED_VALUE"""),171916.0) -> 171916 | D31: =IFERROR(__xludf.DUMMYFUNCTION("""COMPUTED_VALUE"""),"Mystic Matrimony Special Collection Bonus ") -> Mystic Matrimony Special Collection Bonus | E31: =IFERROR(__xludf.DUMMYFUNCTION("""COMPUTED_VALUE"""),"Mystic Matrimony Nobunaga x 1") -> Mystic Matrimony Nobunaga x 1 | F31: Mystic Matrimony Nobunaga | G31: 1 | H31: Mystic Matrimony Special Collection Bonus | N31: 1 | Q31: 46058.272 | R31: 171916▸Mystic Matrimony Special Collection Bonus 〈Mystic Matrimony Nobunaga x 1〉 | S31: =IFERROR(__xludf.DUMMYFUNCTION("""COMPUTED_VALUE"""),171916.0) -> 171916 | T31: =IFERROR(__xludf.DUMMYFUNCTION("""COMPUTED_VALUE"""),"Mystic Matrimony Special Collection Bonus ") -> Mystic Matrimony Special Collection Bonus | U31: =IFERROR(__xludf.DUMMYFUNCTION("""COMPUTED_VALUE"""),"Mystic Matrimony Nobunaga x 1") -> Mystic Matrimony Nobunaga x 1 | V31: Mystic Matrimony Nobunaga
A32: ce_203_bonus_group_023 | I32: 6320▸Mystic Matrimony After Story ～Masamune～ | J32: =IFERROR(__xludf.DUMMYFUNCTION("""COMPUTED_VALUE"""),6320.0) -> 6320 | K32: =IFERROR(__xludf.DUMMYFUNCTION("""COMPUTED_VALUE"""),"Mystic Matrimony After Story ～Masamune～") -> Mystic Matrimony After Story ～Masamune～ | N32: 1 | Q32: 46058.272 | R32: 6320▸Mystic Matrimony After Story ～Masamune～ | S32: =IFERROR(__xludf.DUMMYFUNCTION("""COMPUTED_VALUE"""),6320.0) -> 6320 | T32: =IFERROR(__xludf.DUMMYFUNCTION("""COMPUTED_VALUE"""),"Mystic Matrimony After Story ～Masamune～") -> Mystic Matrimony After Story ～Masamune～
A33: ce_203_bonus_group_023 | N33: 1 | Q33: 46058.272 | R33: #N/A
A34: ce_203_bonus_group_023 | B34: 171918▸Mystic Matrimony Special Collection Bonus 〈Mystic Matrimony Masamune x 1〉 | C34: =IFERROR(__xludf.DUMMYFUNCTION("""COMPUTED_VALUE"""),171918.0) -> 171918 | D34: =IFERROR(__xludf.DUMMYFUNCTION("""COMPUTED_VALUE"""),"Mystic Matrimony Special Collection Bonus ") -> Mystic Matrimony Special Collection Bonus | E34: =IFERROR(__xludf.DUMMYFUNCTION("""COMPUTED_VALUE"""),"Mystic Matrimony Masamune x 1") -> Mystic Matrimony Masamune x 1 | F34: Mystic Matrimony Masamune | G34: 1 | H34: Mystic Matrimony Special Collection Bonus | N34: 1 | Q34: 46058.272 | R34: 171918▸Mystic Matrimony Special Collection Bonus 〈Mystic Matrimony Masamune x 1〉 | S34: =IFERROR(__xludf.DUMMYFUNCTION("""COMPUTED_VALUE"""),171918.0) -> 171918 | T34: =IFERROR(__xludf.DUMMYFUNCTION("""COMPUTED_VALUE"""),"Mystic Matrimony Special Collection Bonus ") -> Mystic Matrimony Special Collection Bonus | U34: =IFERROR(__xludf.DUMMYFUNCTION("""COMPUTED_VALUE"""),"Mystic Matrimony Masamune x 1") -> Mystic Matrimony Masamune x 1 | V34: Mystic Matrimony Masamune
A35: ce_203_bonus_group_024 | B35: 171923▸Mystic Matrimony Ranking Bonus 〈Mystic Matrimony Top Ranker Placard x 1〉 | C35: =IFERROR(__xludf.DUMMYFUNCTION("""COMPUTED_VALUE"""),171923.0) -> 171923 | D35: =IFERROR(__xludf.DUMMYFUNCTION("""COMPUTED_VALUE"""),"Mystic Matrimony Ranking Bonus ") -> Mystic Matrimony Ranking Bonus | E35: =IFERROR(__xludf.DUMMYFUNCTION("""COMPUTED_VALUE"""),"Mystic Matrimony Top Ranker Placard x 1") -> Mystic Matrimony Top Ranker Placard x 1 | F35: Mystic Matrimony Top Ranker Placard | G35: 1 | H35: Mystic Matrimony Ranking Bonus | N35: 1 | Q35: 46058.272 | R35: 171923▸Mystic Matrimony Ranking Bonus 〈Mystic Matrimony Top Ranker Placard x 1〉 | S35: =IFERROR(__xludf.DUMMYFUNCTION("""COMPUTED_VALUE"""),171923.0) -> 171923 | T35: =IFERROR(__xludf.DUMMYFUNCTION("""COMPUTED_VALUE"""),"Mystic Matrimony Ranking Bonus ") -> Mystic Matrimony Ranking Bonus | U35: =IFERROR(__xludf.DUMMYFUNCTION("""COMPUTED_VALUE"""),"Mystic Matrimony Top Ranker Placard x 1") -> Mystic Matrimony Top Ranker Placard x 1 | V35: Mystic Matrimony Top Ranker Placard
A36: ce_203_bonus_group_024 | B36: 171924▸Mystic Matrimony Ranking Bonus 〈Enchanted Cobalt Green Kimono x 1〉 | C36: =IFERROR(__xludf.DUMMYFUNCTION("""COMPUTED_VALUE"""),171924.0) -> 171924 | D36: =IFERROR(__xludf.DUMMYFUNCTION("""COMPUTED_VALUE"""),"Mystic Matrimony Ranking Bonus ") -> Mystic Matrimony Ranking Bonus | E36: =IFERROR(__xludf.DUMMYFUNCTION("""COMPUTED_VALUE"""),"Enchanted Cobalt Green Kimono x 1") -> Enchanted Cobalt Green Kimono x 1 | F36: Enchanted Cobalt Green Kimono | G36: 1 | H36: Mystic Matrimony Ranking Bonus | N36: 1 | Q36: 46058.272 | R36: 171924▸Mystic Matrimony Ranking Bonus 〈Enchanted Cobalt Green Kimono x 1〉 | S36: =IFERROR(__xludf.DUMMYFUNCTION("""COMPUTED_VALUE"""),171924.0) -> 171924 | T36: =IFERROR(__xludf.DUMMYFUNCTION("""COMPUTED_VALUE"""),"Mystic Matrimony Ranking Bonus ") -> Mystic Matrimony Ranking Bonus | U36: =IFERROR(__xludf.DUMMYFUNCTION("""COMPUTED_VALUE"""),"Enchanted Cobalt Green Kimono x 1") -> Enchanted Cobalt Green Kimono x 1 | V36: Enchanted Cobalt Green Kimono
A37: ce_203_bonus_group_024 | B37: 171925▸Mystic Matrimony Ranking Bonus 〈His Ogre Ensemble x 1〉 | C37: =IFERROR(__xludf.DUMMYFUNCTION("""COMPUTED_VALUE"""),171925.0) -> 171925 | D37: =IFERROR(__xludf.DUMMYFUNCTION("""COMPUTED_VALUE"""),"Mystic Matrimony Ranking Bonus ") -> Mystic Matrimony Ranking Bonus | E37: =IFERROR(__xludf.DUMMYFUNCTION("""COMPUTED_VALUE"""),"His Ogre Ensemble x 1") -> His Ogre Ensemble x 1 | F37: His Ogre Ensemble | G37: 1 | H37: Mystic Matrimony Ranking Bonus | N37: 1 | Q37: 46058.272 | R37: 171925▸Mystic Matrimony Ranking Bonus 〈His Ogre Ensemble x 1〉 | S37: =IFERROR(__xludf.DUMMYFUNCTION("""COMPUTED_VALUE"""),171925.0) -> 171925 | T37: =IFERROR(__xludf.DUMMYFUNCTION("""COMPUTED_VALUE"""),"Mystic Matrimony Ranking Bonus ") -> Mystic Matrimony Ranking Bonus | U37: =IFERROR(__xludf.DUMMYFUNCTION("""COMPUTED_VALUE"""),"His Ogre Ensemble x 1") -> His Ogre Ensemble x 1 | V37: His Ogre Ensemble
A38: ce_203_bonus_group_024 | B38: 171926▸Mystic Matrimony Ranking Bonus 〈His Draconic Dressrobes x 1〉 | C38: =IFERROR(__xludf.DUMMYFUNCTION("""COMPUTED_VALUE"""),171926.0) -> 171926 | D38: =IFERROR(__xludf.DUMMYFUNCTION("""COMPUTED_VALUE"""),"Mystic Matrimony Ranking Bonus ") -> Mystic Matrimony Ranking Bonus | E38: =IFERROR(__xludf.DUMMYFUNCTION("""COMPUTED_VALUE"""),"His Draconic Dressrobes x 1") -> His Draconic Dressrobes x 1 | F38: His Draconic Dressrobes | G38: 1 | H38: Mystic Matrimony Ranking Bonus | N38: 1 | Q38: 46058.272 | R38: 171926▸Mystic Matrimony Ranking Bonus 〈His Draconic Dressrobes x 1〉 | S38: =IFERROR(__xludf.DUMMYFUNCTION("""COMPUTED_VALUE"""),171926.0) -> 171926 | T38: =IFERROR(__xludf.DUMMYFUNCTION("""COMPUTED_VALUE"""),"Mystic Matrimony Ranking Bonus ") -> Mystic Matrimony Ranking Bonus | U38: =IFERROR(__xludf.DUMMYFUNCTION("""COMPUTED_VALUE"""),"His Draconic Dressrobes x 1") -> His Draconic Dressrobes x 1 | V38: His Draconic Dressrobes
A39: ce_203_bonus_group_024 | B39: 171927▸Mystic Matrimony Ranking Bonus 〈His Vampiric Vestments x 1〉 | C39: =IFERROR(__xludf.DUMMYFUNCTION("""COMPUTED_VALUE"""),171927.0) -> 171927 | D39: =IFERROR(__xludf.DUMMYFUNCTION("""COMPUTED_VALUE"""),"Mystic Matrimony Ranking Bonus ") -> Mystic Matrimony Ranking Bonus | E39: =IFERROR(__xludf.DUMMYFUNCTION("""COMPUTED_VALUE"""),"His Vampiric Vestments x 1") -> His Vampiric Vestments x 1 | F39: His Vampiric Vestments | G39: 1 | H39: Mystic Matrimony Ranking Bonus | N39: 1 | Q39: 46058.272 | R39: 171927▸Mystic Matrimony Ranking Bonus 〈His Vampiric Vestments x 1〉 | S39: =IFERROR(__xludf.DUMMYFUNCTION("""COMPUTED_VALUE"""),171927.0) -> 171927 | T39: =IFERROR(__xludf.DUMMYFUNCTION("""COMPUTED_VALUE"""),"Mystic Matrimony Ranking Bonus ") -> Mystic Matrimony Ranking Bonus | U39: =IFERROR(__xludf.DUMMYFUNCTION("""COMPUTED_VALUE"""),"His Vampiric Vestments x 1") -> His Vampiric Vestments x 1 | V39: His Vampiric Vestments
A40: ce_203_bonus_group_024 | B40: 171928▸Mystic Matrimony Ranking Bonus 〈Nine-Tailed Fox Warlords 1 x 1〉 | C40: =IFERROR(__xludf.DUMMYFUNCTION("""COMPUTED_VALUE"""),171928.0) -> 171928 | D40: =IFERROR(__xludf.DUMMYFUNCTION("""COMPUTED_VALUE"""),"Mystic Matrimony Ranking Bonus ") -> Mystic Matrimony Ranking Bonus | E40: =IFERROR(__xludf.DUMMYFUNCTION("""COMPUTED_VALUE"""),"Nine-Tailed Fox Warlords 1 x 1") -> Nine-Tailed Fox Warlords 1 x 1 | F40: Nine-Tailed Fox Warlords 1 | G40: 1 | H40: Mystic Matrimony Ranking Bonus | N40: 1 | Q40: 46058.272 | R40: 171928▸Mystic Matrimony Ranking Bonus 〈Nine-Tailed Fox Warlords 1 x 1〉 | S40: =IFERROR(__xludf.DUMMYFUNCTION("""COMPUTED_VALUE"""),171928.0) -> 171928 | T40: =IFERROR(__xludf.DUMMYFUNCTION("""COMPUTED_VALUE"""),"Mystic Matrimony Ranking Bonus ") -> Mystic Matrimony Ranking Bonus | U40: =IFERROR(__xludf.DUMMYFUNCTION("""COMPUTED_VALUE"""),"Nine-Tailed Fox Warlords 1 x 1") -> Nine-Tailed Fox Warlords 1 x 1 | V40: Nine-Tailed Fox Warlords 1
...

Sheet ExtraBounus
A1: https://common-legacy-app-admin.us.ikemen-sengoku.jp/admin/isgame/collection/all_setting/203#event_linked_bonus_mst
A3: {=SEQUENCE(1,COLUMNS(A5:AA8))} -> 1 | B3: 2 | C3: 3 | D3: 4 | E3: 5 | F3: 6 | G3: 7 | H3: 8 | I3: 9 | J3: 10 | K3: 11 | L3: 12 | M3: 13 | N3: 14 | O3: 15 | P3: 16 | Q3: 17 | R3: 18 | S3: 19 | T3: 20 | U3: 21 | V3: 22 | W3: 23 | X3: 24 | Y3: 25 | Z3: 26 | AA3: 27
A4: ID | B4: order | C4: chapter / ticket | D4: chapter | E4: ticket | F4: route | G4: collect item quantity | H4: chara | I4: character first name | J4: last name | K4: type | L4: receive title | M4: attention | N4: thumbnail | O4: frame | P4: start | Q4: end | R4: present | S4: present ID | T4: present Name | U4: present Item | V4: present Item Name | W4: present Item count | X4: special story | Y4: voice | Z4: still | AA4: update
A5: 249 | B5: 1 | C5: 13 / 10 | D5: =IFERROR(__xludf.DUMMYFUNCTION("ARRAYFORMULA(IF(ISTEXT(C5:C8),VALUE(SPLIT(C5:C8,""▸〈〉/"")),))"),13.0) -> 13 | E5: =IFERROR(__xludf.DUMMYFUNCTION("""COMPUTED_VALUE"""),10.0) -> 10 | F5: 全ルート | G5: 500 | H5: Yoshimoto Imagawa | I5: =IFERROR(__xludf.DUMMYFUNCTION("ARRAYFORMULA(IF(ISTEXT(H5:H8),SPLIT(H5:H8,""▸〈〉/ ""),))"),"Yoshimoto") -> Yoshimoto | J5: =IFERROR(__xludf.DUMMYFUNCTION("""COMPUTED_VALUE"""),"Imagawa") -> Imagawa | K5: avatar | L5: You got the reward! | N5: 692_084.png | O5: thumb_2.png | P5: 46074.708 | Q5: 46080.708 | R5: 171919▸Mystic Matrimony Extra Bonus 〈Nine-Tailed Fox Yoshimoto x 1〉 | S5: =IFERROR(__xludf.DUMMYFUNCTION("ARRAYFORMULA(IF(ISTEXT(R5:R8),TRIM(SPLIT(R5:R8,""▸〈〉/"")),))"),"171919") -> 171919 | T5: =IFERROR(__xludf.DUMMYFUNCTION("""COMPUTED_VALUE"""),"Mystic Matrimony Extra Bonus") -> Mystic Matrimony Extra Bonus | U5: =IFERROR(__xludf.DUMMYFUNCTION("""COMPUTED_VALUE"""),"Nine-Tailed Fox Yoshimoto x 1") -> Nine-Tailed Fox Yoshimoto x 1 | V5: {=TRIM(LEFT(U5:U8,LEN(U5:U8)-4))} -> Nine-Tailed Fox Yoshimoto | W5: {=VALUE(RIGHT(U5:U8,1))} -> 1 | AA5: 46058.274
A6: 250 | B6: 1 | C6: 13 / 10 | D6: =IFERROR(__xludf.DUMMYFUNCTION("""COMPUTED_VALUE"""),13.0) -> 13 | E6: =IFERROR(__xludf.DUMMYFUNCTION("""COMPUTED_VALUE"""),10.0) -> 10 | F6: 全ルート | G6: 500 | H6: Motonari Mouri | I6: =IFERROR(__xludf.DUMMYFUNCTION("""COMPUTED_VALUE"""),"Motonari") -> Motonari | J6: =IFERROR(__xludf.DUMMYFUNCTION("""COMPUTED_VALUE"""),"Mouri") -> Mouri | K6: avatar | L6: You got the reward! | N6: 651_068.png | O6: thumb_2.png | P6: 46074.708 | Q6: 46080.708 | R6: 171920▸Mystic Matrimony Extra Bonus 〈Nine-Tailed Fox Motonari x 1〉 | S6: =IFERROR(__xludf.DUMMYFUNCTION("""COMPUTED_VALUE"""),"171920") -> 171920 | T6: =IFERROR(__xludf.DUMMYFUNCTION("""COMPUTED_VALUE"""),"Mystic Matrimony Extra Bonus") -> Mystic Matrimony Extra Bonus | U6: =IFERROR(__xludf.DUMMYFUNCTION("""COMPUTED_VALUE"""),"Nine-Tailed Fox Motonari x 1") -> Nine-Tailed Fox Motonari x 1 | V6: Nine-Tailed Fox Motonari | W6: 1 | AA6: 46058.274
